2022-01-17 16:17:34,772 WARNING libqtile core.py:grab_key():L459 Can't grab <Key (['mod4'], h)> (unknown keysym: 0x68)
2022-01-17 16:17:34,772 WARNING libqtile core.py:grab_key():L459 Can't grab <Key (['mod4'], l)> (unknown keysym: 0x6c)
2022-01-17 16:17:34,772 WARNING libqtile core.py:grab_key():L459 Can't grab <Key (['mod4'], j)> (unknown keysym: 0x6a)
2022-01-17 16:17:34,772 WARNING libqtile core.py:grab_key():L459 Can't grab <Key (['mod4'], k)> (unknown keysym: 0x6b)
2022-01-17 16:17:34,772 WARNING libqtile core.py:grab_key():L459 Can't grab <Key (['mod4', 'shift'], h)> (unknown keysym: 0x68)
2022-01-17 16:17:34,772 WARNING libqtile core.py:grab_key():L459 Can't grab <Key (['mod4', 'shift'], l)> (unknown keysym: 0x6c)
2022-01-17 16:17:34,772 WARNING libqtile core.py:grab_key():L459 Can't grab <Key (['mod4', 'shift'], j)> (unknown keysym: 0x6a)
2022-01-17 16:17:34,772 WARNING libqtile core.py:grab_key():L459 Can't grab <Key (['mod4', 'shift'], k)> (unknown keysym: 0x6b)
2022-01-17 16:17:34,772 WARNING libqtile core.py:grab_key():L459 Can't grab <Key (['mod4', 'control'], h)> (unknown keysym: 0x68)
2022-01-17 16:17:34,772 WARNING libqtile core.py:grab_key():L459 Can't grab <Key (['mod4', 'control'], l)> (unknown keysym: 0x6c)
2022-01-17 16:17:34,772 WARNING libqtile core.py:grab_key():L459 Can't grab <Key (['mod4', 'control'], j)> (unknown keysym: 0x6a)
2022-01-17 16:17:34,772 WARNING libqtile core.py:grab_key():L459 Can't grab <Key (['mod4', 'control'], k)> (unknown keysym: 0x6b)
2022-01-17 16:17:34,772 WARNING libqtile core.py:grab_key():L459 Can't grab <Key (['mod4'], n)> (unknown keysym: 0x6e)
2022-01-17 16:17:34,772 WARNING libqtile core.py:grab_key():L459 Can't grab <Key (['mod4'], w)> (unknown keysym: 0x77)
2022-01-17 16:17:34,772 WARNING libqtile core.py:grab_key():L459 Can't grab <Key (['mod4', 'control'], r)> (unknown keysym: 0x72)
2022-01-17 16:17:34,772 WARNING libqtile core.py:grab_key():L459 Can't grab <Key (['mod4', 'control'], q)> (unknown keysym: 0x71)
2022-01-17 16:17:34,772 WARNING libqtile core.py:grab_key():L459 Can't grab <Key (['mod4'], r)> (unknown keysym: 0x72)
2022-01-17 16:17:34,773 WARNING libqtile core.py:grab_key():L459 Can't grab <Key (['mod4'], 1)> (unknown keysym: 0x31)
2022-01-17 16:17:34,773 WARNING libqtile core.py:grab_key():L459 Can't grab <Key (['mod4', 'shift'], 1)> (unknown keysym: 0x31)
2022-01-17 16:17:34,773 WARNING libqtile core.py:grab_key():L459 Can't grab <Key (['mod4'], 2)> (unknown keysym: 0x32)
2022-01-17 16:17:34,773 WARNING libqtile core.py:grab_key():L459 Can't grab <Key (['mod4', 'shift'], 2)> (unknown keysym: 0x32)
2022-01-17 16:17:34,773 WARNING libqtile core.py:grab_key():L459 Can't grab <Key (['mod4'], 3)> (unknown keysym: 0x33)
2022-01-17 16:17:34,773 WARNING libqtile core.py:grab_key():L459 Can't grab <Key (['mod4', 'shift'], 3)> (unknown keysym: 0x33)
2022-01-17 16:17:34,773 WARNING libqtile core.py:grab_key():L459 Can't grab <Key (['mod4'], 4)> (unknown keysym: 0x34)
2022-01-17 16:17:34,773 WARNING libqtile core.py:grab_key():L459 Can't grab <Key (['mod4', 'shift'], 4)> (unknown keysym: 0x34)
2022-01-17 16:17:34,773 WARNING libqtile core.py:grab_key():L459 Can't grab <Key (['mod4'], 5)> (unknown keysym: 0x35)
2022-01-17 16:17:34,773 WARNING libqtile core.py:grab_key():L459 Can't grab <Key (['mod4', 'shift'], 5)> (unknown keysym: 0x35)
2022-01-17 16:17:34,773 WARNING libqtile core.py:grab_key():L459 Can't grab <Key (['mod4'], 6)> (unknown keysym: 0x36)
2022-01-17 16:17:34,773 WARNING libqtile core.py:grab_key():L459 Can't grab <Key (['mod4', 'shift'], 6)> (unknown keysym: 0x36)
2022-01-17 16:17:34,773 WARNING libqtile core.py:grab_key():L459 Can't grab <Key (['mod4'], 7)> (unknown keysym: 0x37)
2022-01-17 16:17:34,773 WARNING libqtile core.py:grab_key():L459 Can't grab <Key (['mod4', 'shift'], 7)> (unknown keysym: 0x37)
2022-01-17 16:17:34,773 WARNING libqtile core.py:grab_key():L459 Can't grab <Key (['mod4'], 8)> (unknown keysym: 0x38)
2022-01-17 16:17:34,773 WARNING libqtile core.py:grab_key():L459 Can't grab <Key (['mod4', 'shift'], 8)> (unknown keysym: 0x38)
2022-01-17 16:17:34,773 WARNING libqtile core.py:grab_key():L459 Can't grab <Key (['mod4'], 9)> (unknown keysym: 0x39)
2022-01-17 16:17:34,773 WARNING libqtile core.py:grab_key():L459 Can't grab <Key (['mod4', 'shift'], 9)> (unknown keysym: 0x39)
2022-01-17 18:21:47,888 WARNING libqtile core.py:grab_key():L459 Can't grab <Key (['mod4'], h)> (unknown keysym: 0x68)
2022-01-17 18:21:47,888 WARNING libqtile core.py:grab_key():L459 Can't grab <Key (['mod4'], l)> (unknown keysym: 0x6c)
2022-01-17 18:21:47,889 WARNING libqtile core.py:grab_key():L459 Can't grab <Key (['mod4'], j)> (unknown keysym: 0x6a)
2022-01-17 18:21:47,889 WARNING libqtile core.py:grab_key():L459 Can't grab <Key (['mod4'], k)> (unknown keysym: 0x6b)
2022-01-17 18:21:47,889 WARNING libqtile core.py:grab_key():L459 Can't grab <Key (['mod4', 'shift'], h)> (unknown keysym: 0x68)
2022-01-17 18:21:47,889 WARNING libqtile core.py:grab_key():L459 Can't grab <Key (['mod4', 'shift'], l)> (unknown keysym: 0x6c)
2022-01-17 18:21:47,889 WARNING libqtile core.py:grab_key():L459 Can't grab <Key (['mod4', 'shift'], j)> (unknown keysym: 0x6a)
2022-01-17 18:21:47,889 WARNING libqtile core.py:grab_key():L459 Can't grab <Key (['mod4', 'shift'], k)> (unknown keysym: 0x6b)
2022-01-17 18:21:47,889 WARNING libqtile core.py:grab_key():L459 Can't grab <Key (['mod4', 'control'], h)> (unknown keysym: 0x68)
2022-01-17 18:21:47,890 WARNING libqtile core.py:grab_key():L459 Can't grab <Key (['mod4', 'control'], l)> (unknown keysym: 0x6c)
2022-01-17 18:21:47,890 WARNING libqtile core.py:grab_key():L459 Can't grab <Key (['mod4', 'control'], j)> (unknown keysym: 0x6a)
2022-01-17 18:21:47,890 WARNING libqtile core.py:grab_key():L459 Can't grab <Key (['mod4', 'control'], k)> (unknown keysym: 0x6b)
2022-01-17 18:21:47,890 WARNING libqtile core.py:grab_key():L459 Can't grab <Key (['mod4'], n)> (unknown keysym: 0x6e)
2022-01-17 18:21:47,890 WARNING libqtile core.py:grab_key():L459 Can't grab <Key (['mod4'], w)> (unknown keysym: 0x77)
2022-01-17 18:21:47,890 WARNING libqtile core.py:grab_key():L459 Can't grab <Key (['mod4', 'control'], r)> (unknown keysym: 0x72)
2022-01-17 18:21:47,890 WARNING libqtile core.py:grab_key():L459 Can't grab <Key (['mod4', 'control'], q)> (unknown keysym: 0x71)
2022-01-17 18:21:47,890 WARNING libqtile core.py:grab_key():L459 Can't grab <Key (['mod4'], r)> (unknown keysym: 0x72)
2022-01-17 19:25:56,304 ERROR libqtile core.py:get_interesting_pid():L810 Got an exception in getting the window pid
Traceback (most recent call last):
  File "/usr/lib/python3.10/site-packages/xcffib/__init__.py", line 571, in wrapper
    return f(*args)
  File "/usr/lib/python3.10/site-packages/xcffib/__init__.py", line 658, in wait_for_reply
    self._process_error(error_p[0])
  File "/usr/lib/python3.10/site-packages/xcffib/__init__.py", line 645, in _process_error
    self.invalid()
  File "/usr/lib/python3.10/site-packages/xcffib/__init__.py", line 559, in invalid
    raise ConnectionException(err)
xcffib.ConnectionException: xcb connection errors because of socket, pipe and other stream errors.

During handling of the above exception, another exception occurred:

Traceback (most recent call last):
  File "/usr/lib/python3.10/site-packages/libqtile/backend/x11/core.py", line 808, in get_interesting_pid
    return win.window.get_net_wm_pid()
  File "/usr/lib/python3.10/site-packages/libqtile/backend/x11/window.py", line 284, in get_net_wm_pid
    r = self.get_property("_NET_WM_PID", unpack=int)
  File "/usr/lib/python3.10/site-packages/libqtile/backend/x11/window.py", line 386, in get_property
    ).reply()
  File "/usr/lib/python3.10/site-packages/xcffib/__init__.py", line 332, in reply
    data = self.conn.wait_for_reply(self.sequence)
  File "/usr/lib/python3.10/site-packages/xcffib/__init__.py", line 573, in wrapper
    self.invalid()
  File "/usr/lib/python3.10/site-packages/xcffib/__init__.py", line 559, in invalid
    raise ConnectionException(err)
xcffib.ConnectionException: xcb connection errors because of socket, pipe and other stream errors.
2022-01-17 19:25:56,307 ERROR libqtile manager.py:_finalize_configurables():L294 exception during finalize
Traceback (most recent call last):
  File "/usr/lib/python3.10/site-packages/libqtile/core/manager.py", line 284, in _finalize_configurables
    widget.finalize()
  File "/usr/lib/python3.10/site-packages/libqtile/widget/base.py", line 232, in finalize
    self.drawer.finalize()
  File "/usr/lib/python3.10/site-packages/libqtile/backend/x11/drawer.py", line 36, in finalize
    self._free_pixmap()
  File "/usr/lib/python3.10/site-packages/libqtile/backend/x11/drawer.py", line 116, in _free_pixmap
    self.qtile.core.conn.conn.core.FreePixmap(self._pixmap)
  File "/usr/lib/python3.10/site-packages/xcffib/xproto.py", line 2863, in FreePixmap
    return self.send_request(54, buf, is_checked=is_checked)
  File "/usr/lib/python3.10/site-packages/xcffib/__init__.py", line 391, in send_request
    seq = self.conn.send_request(flags, xcb_parts + 2, xcb_req)
  File "/usr/lib/python3.10/site-packages/xcffib/__init__.py", line 569, in wrapper
    self.invalid()
  File "/usr/lib/python3.10/site-packages/xcffib/__init__.py", line 559, in invalid
    raise ConnectionException(err)
xcffib.ConnectionException: xcb connection errors because of socket, pipe and other stream errors.
2022-01-17 19:25:56,308 ERROR libqtile core.py:_xpoll():L328 Shutting down due to X connection error XCB_CONN_ERROR (1)
Traceback (most recent call last):
  File "/usr/lib/python3.10/site-packages/libqtile/backend/x11/core.py", line 290, in _xpoll
    event = self.conn.conn.poll_for_event()
  File "/usr/lib/python3.10/site-packages/xcffib/__init__.py", line 569, in wrapper
    self.invalid()
  File "/usr/lib/python3.10/site-packages/xcffib/__init__.py", line 559, in invalid
    raise ConnectionException(err)
xcffib.ConnectionException: xcb connection errors because of socket, pipe and other stream errors.
2022-01-17 19:25:56,308 ERROR libqtile core.py:get_interesting_pid():L810 Got an exception in getting the window pid
Traceback (most recent call last):
  File "/usr/lib/python3.10/site-packages/libqtile/backend/x11/core.py", line 290, in _xpoll
    event = self.conn.conn.poll_for_event()
  File "/usr/lib/python3.10/site-packages/xcffib/__init__.py", line 569, in wrapper
    self.invalid()
  File "/usr/lib/python3.10/site-packages/xcffib/__init__.py", line 559, in invalid
    raise ConnectionException(err)
xcffib.ConnectionException: xcb connection errors because of socket, pipe and other stream errors.

During handling of the above exception, another exception occurred:

Traceback (most recent call last):
  File "/usr/lib/python3.10/site-packages/libqtile/backend/x11/core.py", line 808, in get_interesting_pid
    return win.window.get_net_wm_pid()
  File "/usr/lib/python3.10/site-packages/libqtile/backend/x11/window.py", line 284, in get_net_wm_pid
    r = self.get_property("_NET_WM_PID", unpack=int)
  File "/usr/lib/python3.10/site-packages/libqtile/backend/x11/window.py", line 377, in get_property
    r = self.conn.conn.core.GetProperty(
  File "/usr/lib/python3.10/site-packages/xcffib/xproto.py", line 2720, in GetProperty
    return self.send_request(20, buf, GetPropertyCookie, is_checked=is_checked)
  File "/usr/lib/python3.10/site-packages/xcffib/__init__.py", line 391, in send_request
    seq = self.conn.send_request(flags, xcb_parts + 2, xcb_req)
  File "/usr/lib/python3.10/site-packages/xcffib/__init__.py", line 569, in wrapper
    self.invalid()
  File "/usr/lib/python3.10/site-packages/xcffib/__init__.py", line 559, in invalid
    raise ConnectionException(err)
xcffib.ConnectionException: xcb connection errors because of socket, pipe and other stream errors.
2022-01-17 19:25:56,308 ERROR libqtile core.py:get_interesting_pid():L810 Got an exception in getting the window pid
Traceback (most recent call last):
  File "/usr/lib/python3.10/site-packages/libqtile/backend/x11/core.py", line 808, in get_interesting_pid
    return win.window.get_net_wm_pid()
  File "/usr/lib/python3.10/site-packages/libqtile/backend/x11/window.py", line 284, in get_net_wm_pid
    r = self.get_property("_NET_WM_PID", unpack=int)
  File "/usr/lib/python3.10/site-packages/libqtile/backend/x11/window.py", line 377, in get_property
    r = self.conn.conn.core.GetProperty(
  File "/usr/lib/python3.10/site-packages/xcffib/xproto.py", line 2720, in GetProperty
    return self.send_request(20, buf, GetPropertyCookie, is_checked=is_checked)
  File "/usr/lib/python3.10/site-packages/xcffib/__init__.py", line 391, in send_request
    seq = self.conn.send_request(flags, xcb_parts + 2, xcb_req)
  File "/usr/lib/python3.10/site-packages/xcffib/__init__.py", line 569, in wrapper
    self.invalid()
  File "/usr/lib/python3.10/site-packages/xcffib/__init__.py", line 559, in invalid
    raise ConnectionException(err)
xcffib.ConnectionException: xcb connection errors because of socket, pipe and other stream errors.
2022-01-17 19:25:56,309 ERROR libqtile start.py:start():L91 Qtile crashed
Traceback (most recent call last):
  File "/usr/lib/python3.10/site-packages/libqtile/scripts/start.py", line 89, in start
    q.loop()
  File "/usr/lib/python3.10/site-packages/libqtile/core/manager.py", line 195, in loop
    asyncio.run(self.async_loop())
  File "/usr/lib/python3.10/asyncio/runners.py", line 44, in run
    return loop.run_until_complete(main)
  File "/usr/lib/python3.10/asyncio/base_events.py", line 641, in run_until_complete
    return future.result()
  File "/usr/lib/python3.10/site-packages/libqtile/core/manager.py", line 221, in async_loop
    self.finalize()
  File "/usr/lib/python3.10/site-packages/libqtile/core/manager.py", line 299, in finalize
    self.core.finalize()
  File "/usr/lib/python3.10/site-packages/libqtile/backend/x11/core.py", line 171, in finalize
    self.conn.conn.core.DeletePropertyChecked(
  File "/usr/lib/python3.10/site-packages/xcffib/xproto.py", line 2716, in DeleteProperty
    return self.send_request(19, buf, is_checked=is_checked)
  File "/usr/lib/python3.10/site-packages/xcffib/__init__.py", line 391, in send_request
    seq = self.conn.send_request(flags, xcb_parts + 2, xcb_req)
  File "/usr/lib/python3.10/site-packages/xcffib/__init__.py", line 569, in wrapper
    self.invalid()
  File "/usr/lib/python3.10/site-packages/xcffib/__init__.py", line 559, in invalid
    raise ConnectionException(err)
xcffib.ConnectionException: xcb connection errors because of socket, pipe and other stream errors.
2022-01-17 19:25:56,309 WARNING libqtile lifecycle.py:_atexit():L38 Qtile will now terminate
